[{"ContainerToolsException.Message":"Visual Studio Container Tools requires Docker to be running before building, debugging or running a containerized project.  For more info, please see: https://aka.ms/DockerToolsTroubleshooting","ContainerToolsException.ErrorCode":"","ContainerToolsException.StackTrace":"","ContainerToolsException.HResult":"-2146233088","ContainerToolsException.InnerException":"Microsoft.VisualStudio.Containers.Tools.Common.ContainerToolsException: docker.errors.DockerException: Error while fetching server API version: ('Connection aborted.', FileNotFoundError(2, 'No such file or directory'))\nIf the error persists, try restarting Docker Desktop.\n ---> Microsoft.VisualStudio.Containers.Tools.Common.ContainerToolsException: docker.errors.DockerException: Error while fetching server API version: ('Connection aborted.', FileNotFoundError(2, 'No such file or directory'))\n   at Microsoft.Docker.DockerWorkspace.PrepareForLaunchAsync(DockerDevelopmentMode dockerDevelopmentMode, Boolean noBuild, IDockerLogger logger, String dockerComposeUpArguments, CancellationToken cancellationToken)\nError code: DT1001\nSeverity: Error\nCommand line: docker-compose  -f \"/Users/adrianbooth67/Projects/Viridia/Device Monitoring Platform/Monitoring/docker-compose.yml\" -f \"/Users/adrianbooth67/Projects/Viridia/Device Monitoring Platform/Monitoring/docker-compose.override.yml\" -f \"/Users/adrianbooth67/Projects/Viridia/Device Monitoring Platform/Monitoring/obj/Docker/docker-compose.vs.debug.g.yml\" -p dockercompose1118994426062358019 --no-ansi up -d --build --remove-orphans\nCommand exit code: 255\nCommand output: \nCommand error: [49521] Failed to execute script docker-compose\nTraceback (most recent call last):\n  File \"site-packages/urllib3/connectionpool.py\", line 677, in urlopen\n  File \"site-packages/urllib3/connectionpool.py\", line 392, in _make_request\n  File \"http/client.py\", line 1252, in request\n  File \"http/client.py\", line 1298, in _send_request\n  File \"http/client.py\", line 1247, in endheaders\n  File \"http/client.py\", line 1026, in _send_output\n  File \"http/client.py\", line 966, in send\n  File \"site-packages/docker/transport/unixconn.py\", line 43, in connect\nFileNotFoundError: [Errno 2] No such file or directory\nDuring handling of the above exception, another exception occurred:\nTraceback (most recent call last):\n  File \"site-packages/requests/adapters.py\", line 449, in send\n  File \"site-packages/urllib3/connectionpool.py\", line 727, in urlopen\n  File \"site-packages/urllib3/util/retry.py\", line 403, in increment\n  File \"site-packages/urllib3/packages/six.py\", line 734, in reraise\n  File \"site-packages/urllib3/connectionpool.py\", line 677, in urlopen\n  File \"site-packages/urllib3/connectionpool.py\", line 392, in _make_request\n  File \"http/client.py\", line 1252, in request\n  File \"http/client.py\", line 1298, in _send_request\n  File \"http/client.py\", line 1247, in endheaders\n  File \"http/client.py\", line 1026, in _send_output\n  File \"http/client.py\", line 966, in send\n  File \"site-packages/docker/transport/unixconn.py\", line 43, in connect\nurllib3.exceptions.ProtocolError: ('Connection aborted.', FileNotFoundError(2, 'No such file or directory'))\nDuring handling of the above exception, another exception occurred:\nTraceback (most recent call last):\n  File \"site-packages/docker/api/client.py\", line 205, in _retrieve_server_version\n  File \"site-packages/docker/api/daemon.py\", line 181, in version\n  File \"site-packages/docker/utils/decorators.py\", line 46, in inner\n  File \"site-packages/docker/api/client.py\", line 228, in _get\n  File \"site-packages/requests/sessions.py\", line 543, in get\n  File \"site-packages/requests/sessions.py\", line 530, in request\n  File \"site-packages/requests/sessions.py\", line 643, in send\n  File \"site-packages/requests/adapters.py\", line 498, in send\nrequests.exceptions.ConnectionError: ('Connection aborted.', FileNotFoundError(2, 'No such file or directory'))\nDuring handling of the above exception, another exception occurred:\nTraceback (most recent call last):\n  File \"docker-compose\", line 3, in <module>\n  File \"compose/cli/main.py\", line 67, in main\n  File \"compose/cli/main.py\", line 123, in perform_command\n  File \"compose/cli/command.py\", line 69, in project_from_options\n  File \"compose/cli/command.py\", line 132, in get_project\n  File \"compose/cli/docker_client.py\", line 43, in get_client\n  File \"compose/cli/docker_client.py\", line 170, in docker_client\n  File \"site-packages/docker/api/client.py\", line 188, in __init__\n  File \"site-packages/docker/api/client.py\", line 213, in _retrieve_server_version\ndocker.errors.DockerException: Error while fetching server API version: ('Connection aborted.', FileNotFoundError(2, 'No such file or directory'))\n\n   --- End of inner exception stack trace ---\n   at Microsoft.Docker.DockerWorkspace.PrepareForLaunchAsync(DockerDevelopmentMode dockerDevelopmentMode, Boolean noBuild, IDockerLogger logger, String dockerComposeUpArguments, CancellationToken cancellationToken)\n   at Microsoft.Docker.BuildTasks.PrepareForLaunch.ExecuteCoreAsync(DockerBuildTaskContext context)\n   at Microsoft.Docker.BuildTasks.DockerBuildTask.ExecuteAsync(DockerBuildTaskContext context)\nError code: DT1001\nSeverity: Error\n"}]